<?xml version="1.0" encoding="UTF-8"?>
<testng-results ignored="0" total="6" passed="0" failed="6" skipped="0">
  <reporter-output>
  </reporter-output>
  <suite started-at="2025-04-13T12:37:02Z" name="ST1048177" finished-at="2025-04-13T12:37:02Z" duration-ms="77">
    <groups>
    </groups>
    <test started-at="2025-04-13T12:37:02Z" name="TestNG tests" finished-at="2025-04-13T12:37:02Z" duration-ms="77">
      <class name="Assignment_1.LoginNGTest">
        <test-method is-config="true" signature="setUpClass()[pri:0, instance:Assignment_1.LoginNGTest@5f282abb]" started-at="2025-04-13T12:37:02Z" name="setUpClass" finished-at="2025-04-13T12:37:02Z" duration-ms="8" status="PASS">
          <reporter-output>
          </reporter-output>
        </test-method> <!-- setUpClass -->
        <test-method is-config="true" signature="setUpMethod()[pri:0, instance:Assignment_1.LoginNGTest@5f282abb]" started-at="2025-04-13T12:37:02Z" name="setUpMethod" finished-at="2025-04-13T12:37:02Z" duration-ms="1" status="PASS">
          <reporter-output>
          </reporter-output>
        </test-method> <!-- setUpMethod -->
        <test-method signature="testCheckLocalPhoneNumber()[pri:0, instance:Assignment_1.LoginNGTest@5f282abb]" started-at="2025-04-13T12:37:02Z" name="testCheckLocalPhoneNumber" finished-at="2025-04-13T12:37:02Z" duration-ms="1" status="FAIL">
          <exception class="java.lang.StringIndexOutOfBoundsException">
            <message>
              <![CDATA[Range [0, 3) out of bounds for length 0]]>
            </message>
            <full-stacktrace>
              <![CDATA[java.lang.StringIndexOutOfBoundsException: Range [0, 3) out of bounds for length 0
at java.base/jdk.internal.util.Preconditions$1.apply(Preconditions.java:55)
at java.base/jdk.internal.util.Preconditions$1.apply(Preconditions.java:52)
at java.base/jdk.internal.util.Preconditions$4.apply(Preconditions.java:213)
at java.base/jdk.internal.util.Preconditions$4.apply(Preconditions.java:210)
at java.base/jdk.internal.util.Preconditions.outOfBounds(Preconditions.java:98)
at java.base/jdk.internal.util.Preconditions.outOfBoundsCheckFromToIndex(Preconditions.java:112)
at java.base/jdk.internal.util.Preconditions.checkFromToIndex(Preconditions.java:349)
at java.base/java.lang.String.checkBoundsBeginEnd(String.java:4963)
at java.base/java.lang.String.substring(String.java:2925)
at Assignment_1.Login.checkLocalPhoneNumber(Login.java:47)
at Assignment_1.LoginNGTest.testCheckLocalPhoneNumber(LoginNGTest.java:78)
at java.base/jdk.internal.reflect.DirectMethodHandleAccessor.invoke(DirectMethodHandleAccessor.java:103)
at java.base/java.lang.reflect.Method.invoke(Method.java:580)
at org.testng.internal.MethodInvocationHelper.invokeMethod(MethodInvocationHelper.java:124)
at org.testng.internal.Invoker.invokeMethod(Invoker.java:583)
at org.testng.internal.Invoker.invokeTestMethod(Invoker.java:719)
at org.testng.internal.Invoker.invokeTestMethods(Invoker.java:989)
at org.testng.internal.TestMethodWorker.invokeTestMethods(TestMethodWorker.java:125)
at org.testng.internal.TestMethodWorker.run(TestMethodWorker.java:109)
at org.testng.TestRunner.privateRun(TestRunner.java:648)
at org.testng.TestRunner.run(TestRunner.java:505)
at org.testng.SuiteRunner.runTest(SuiteRunner.java:455)
at org.testng.SuiteRunner.runSequentially(SuiteRunner.java:450)
at org.testng.SuiteRunner.privateRun(SuiteRunner.java:415)
at org.testng.SuiteRunner.run(SuiteRunner.java:364)
at org.testng.SuiteRunnerWorker.runSuite(SuiteRunnerWorker.java:52)
at org.testng.SuiteRunnerWorker.run(SuiteRunnerWorker.java:84)
at org.testng.TestNG.runSuitesSequentially(TestNG.java:1208)
at org.testng.TestNG.runSuitesLocally(TestNG.java:1137)
at org.testng.TestNG.runSuites(TestNG.java:1049)
at org.testng.TestNG.run(TestNG.java:1017)
at org.testng.TestNG.privateMain(TestNG.java:1354)
at org.testng.TestNG.main(TestNG.java:1323)
]]>
            </full-stacktrace>
          </exception> <!-- java.lang.StringIndexOutOfBoundsException -->
          <reporter-output>
          </reporter-output>
        </test-method> <!-- testCheckLocalPhoneNumber -->
        <test-method is-config="true" signature="tearDownMethod()[pri:0, instance:Assignment_1.LoginNGTest@5f282abb]" started-at="2025-04-13T12:37:02Z" name="tearDownMethod" finished-at="2025-04-13T12:37:02Z" duration-ms="0" status="PASS">
          <reporter-output>
          </reporter-output>
        </test-method> <!-- tearDownMethod -->
        <test-method signature="testCheckPasswordComplexity()[pri:0, instance:Assignment_1.LoginNGTest@5f282abb]" started-at="2025-04-13T12:37:02Z" name="testCheckPasswordComplexity" finished-at="2025-04-13T12:37:02Z" duration-ms="1" status="FAIL">
          <exception class="java.lang.AssertionError">
            <message>
              <![CDATA[The test case is a prototype.]]>
            </message>
            <full-stacktrace>
              <![CDATA[java.lang.AssertionError: The test case is a prototype.
at org.testng.Assert.fail(Assert.java:96)
at Assignment_1.LoginNGTest.testCheckPasswordComplexity(LoginNGTest.java:66)
at java.base/jdk.internal.reflect.DirectMethodHandleAccessor.invoke(DirectMethodHandleAccessor.java:103)
at java.base/java.lang.reflect.Method.invoke(Method.java:580)
at org.testng.internal.MethodInvocationHelper.invokeMethod(MethodInvocationHelper.java:124)
at org.testng.internal.Invoker.invokeMethod(Invoker.java:583)
at org.testng.internal.Invoker.invokeTestMethod(Invoker.java:719)
at org.testng.internal.Invoker.invokeTestMethods(Invoker.java:989)
at org.testng.internal.TestMethodWorker.invokeTestMethods(TestMethodWorker.java:125)
at org.testng.internal.TestMethodWorker.run(TestMethodWorker.java:109)
at org.testng.TestRunner.privateRun(TestRunner.java:648)
at org.testng.TestRunner.run(TestRunner.java:505)
at org.testng.SuiteRunner.runTest(SuiteRunner.java:455)
at org.testng.SuiteRunner.runSequentially(SuiteRunner.java:450)
at org.testng.SuiteRunner.privateRun(SuiteRunner.java:415)
at org.testng.SuiteRunner.run(SuiteRunner.java:364)
at org.testng.SuiteRunnerWorker.runSuite(SuiteRunnerWorker.java:52)
at org.testng.SuiteRunnerWorker.run(SuiteRunnerWorker.java:84)
at org.testng.TestNG.runSuitesSequentially(TestNG.java:1208)
at org.testng.TestNG.runSuitesLocally(TestNG.java:1137)
at org.testng.TestNG.runSuites(TestNG.java:1049)
at org.testng.TestNG.run(TestNG.java:1017)
at org.testng.TestNG.privateMain(TestNG.java:1354)
at org.testng.TestNG.main(TestNG.java:1323)
]]>
            </full-stacktrace>
          </exception> <!-- java.lang.AssertionError -->
          <reporter-output>
          </reporter-output>
        </test-method> <!-- testCheckPasswordComplexity -->
        <test-method is-config="true" signature="setUpMethod()[pri:0, instance:Assignment_1.LoginNGTest@5f282abb]" started-at="2025-04-13T12:37:02Z" name="setUpMethod" finished-at="2025-04-13T12:37:02Z" duration-ms="0" status="PASS">
          <reporter-output>
          </reporter-output>
        </test-method> <!-- setUpMethod -->
        <test-method is-config="true" signature="tearDownMethod()[pri:0, instance:Assignment_1.LoginNGTest@5f282abb]" started-at="2025-04-13T12:37:02Z" name="tearDownMethod" finished-at="2025-04-13T12:37:02Z" duration-ms="1" status="PASS">
          <reporter-output>
          </reporter-output>
        </test-method> <!-- tearDownMethod -->
        <test-method is-config="true" signature="setUpMethod()[pri:0, instance:Assignment_1.LoginNGTest@5f282abb]" started-at="2025-04-13T12:37:02Z" name="setUpMethod" finished-at="2025-04-13T12:37:02Z" duration-ms="0" status="PASS">
          <reporter-output>
          </reporter-output>
        </test-method> <!-- setUpMethod -->
        <test-method signature="testLoginUser()[pri:0, instance:Assignment_1.LoginNGTest@5f282abb]" started-at="2025-04-13T12:37:02Z" name="testLoginUser" finished-at="2025-04-13T12:37:02Z" duration-ms="29" status="FAIL">
          <exception class="java.lang.AssertionError">
            <message>
              <![CDATA[The test case is a prototype.]]>
            </message>
            <full-stacktrace>
              <![CDATA[java.lang.AssertionError: The test case is a prototype.
at org.testng.Assert.fail(Assert.java:96)
at Assignment_1.LoginNGTest.testLoginUser(LoginNGTest.java:114)
at java.base/jdk.internal.reflect.DirectMethodHandleAccessor.invoke(DirectMethodHandleAccessor.java:103)
at java.base/java.lang.reflect.Method.invoke(Method.java:580)
at org.testng.internal.MethodInvocationHelper.invokeMethod(MethodInvocationHelper.java:124)
at org.testng.internal.Invoker.invokeMethod(Invoker.java:583)
at org.testng.internal.Invoker.invokeTestMethod(Invoker.java:719)
at org.testng.internal.Invoker.invokeTestMethods(Invoker.java:989)
at org.testng.internal.TestMethodWorker.invokeTestMethods(TestMethodWorker.java:125)
at org.testng.internal.TestMethodWorker.run(TestMethodWorker.java:109)
at org.testng.TestRunner.privateRun(TestRunner.java:648)
at org.testng.TestRunner.run(TestRunner.java:505)
at org.testng.SuiteRunner.runTest(SuiteRunner.java:455)
at org.testng.SuiteRunner.runSequentially(SuiteRunner.java:450)
at org.testng.SuiteRunner.privateRun(SuiteRunner.java:415)
at org.testng.SuiteRunner.run(SuiteRunner.java:364)
at org.testng.SuiteRunnerWorker.runSuite(SuiteRunnerWorker.java:52)
at org.testng.SuiteRunnerWorker.run(SuiteRunnerWorker.java:84)
at org.testng.TestNG.runSuitesSequentially(TestNG.java:1208)
at org.testng.TestNG.runSuitesLocally(TestNG.java:1137)
at org.testng.TestNG.runSuites(TestNG.java:1049)
at org.testng.TestNG.run(TestNG.java:1017)
at org.testng.TestNG.privateMain(TestNG.java:1354)
at org.testng.TestNG.main(TestNG.java:1323)
]]>
            </full-stacktrace>
          </exception> <!-- java.lang.AssertionError -->
          <reporter-output>
          </reporter-output>
        </test-method> <!-- testLoginUser -->
        <test-method is-config="true" signature="setUpMethod()[pri:0, instance:Assignment_1.LoginNGTest@5f282abb]" started-at="2025-04-13T12:37:02Z" name="setUpMethod" finished-at="2025-04-13T12:37:02Z" duration-ms="0" status="PASS">
          <reporter-output>
          </reporter-output>
        </test-method> <!-- setUpMethod -->
        <test-method signature="testCheckUsername()[pri:0, instance:Assignment_1.LoginNGTest@5f282abb]" started-at="2025-04-13T12:37:02Z" name="testCheckUsername" finished-at="2025-04-13T12:37:02Z" duration-ms="0" status="FAIL">
          <exception class="java.lang.AssertionError">
            <message>
              <![CDATA[The test case is a prototype.]]>
            </message>
            <full-stacktrace>
              <![CDATA[java.lang.AssertionError: The test case is a prototype.
at org.testng.Assert.fail(Assert.java:96)
at Assignment_1.LoginNGTest.testCheckUsername(LoginNGTest.java:51)
at java.base/jdk.internal.reflect.DirectMethodHandleAccessor.invoke(DirectMethodHandleAccessor.java:103)
at java.base/java.lang.reflect.Method.invoke(Method.java:580)
at org.testng.internal.MethodInvocationHelper.invokeMethod(MethodInvocationHelper.java:124)
at org.testng.internal.Invoker.invokeMethod(Invoker.java:583)
at org.testng.internal.Invoker.invokeTestMethod(Invoker.java:719)
at org.testng.internal.Invoker.invokeTestMethods(Invoker.java:989)
at org.testng.internal.TestMethodWorker.invokeTestMethods(TestMethodWorker.java:125)
at org.testng.internal.TestMethodWorker.run(TestMethodWorker.java:109)
at org.testng.TestRunner.privateRun(TestRunner.java:648)
at org.testng.TestRunner.run(TestRunner.java:505)
at org.testng.SuiteRunner.runTest(SuiteRunner.java:455)
at org.testng.SuiteRunner.runSequentially(SuiteRunner.java:450)
at org.testng.SuiteRunner.privateRun(SuiteRunner.java:415)
at org.testng.SuiteRunner.run(SuiteRunner.java:364)
at org.testng.SuiteRunnerWorker.runSuite(SuiteRunnerWorker.java:52)
at org.testng.SuiteRunnerWorker.run(SuiteRunnerWorker.java:84)
at org.testng.TestNG.runSuitesSequentially(TestNG.java:1208)
at org.testng.TestNG.runSuitesLocally(TestNG.java:1137)
at org.testng.TestNG.runSuites(TestNG.java:1049)
at org.testng.TestNG.run(TestNG.java:1017)
at org.testng.TestNG.privateMain(TestNG.java:1354)
at org.testng.TestNG.main(TestNG.java:1323)
]]>
            </full-stacktrace>
          </exception> <!-- java.lang.AssertionError -->
          <reporter-output>
          </reporter-output>
        </test-method> <!-- testCheckUsername -->
        <test-method is-config="true" signature="tearDownMethod()[pri:0, instance:Assignment_1.LoginNGTest@5f282abb]" started-at="2025-04-13T12:37:02Z" name="tearDownMethod" finished-at="2025-04-13T12:37:02Z" duration-ms="0" status="PASS">
          <reporter-output>
          </reporter-output>
        </test-method> <!-- tearDownMethod -->
        <test-method is-config="true" signature="tearDownMethod()[pri:0, instance:Assignment_1.LoginNGTest@5f282abb]" started-at="2025-04-13T12:37:02Z" name="tearDownMethod" finished-at="2025-04-13T12:37:02Z" duration-ms="1" status="PASS">
          <reporter-output>
          </reporter-output>
        </test-method> <!-- tearDownMethod -->
        <test-method is-config="true" signature="setUpMethod()[pri:0, instance:Assignment_1.LoginNGTest@5f282abb]" started-at="2025-04-13T12:37:02Z" name="setUpMethod" finished-at="2025-04-13T12:37:02Z" duration-ms="0" status="PASS">
          <reporter-output>
          </reporter-output>
        </test-method> <!-- setUpMethod -->
        <test-method signature="testRegisterUser()[pri:0, instance:Assignment_1.LoginNGTest@5f282abb]" started-at="2025-04-13T12:37:02Z" name="testRegisterUser" finished-at="2025-04-13T12:37:02Z" duration-ms="1" status="FAIL">
          <exception class="java.lang.UnsupportedOperationException">
            <message>
              <![CDATA[Not supported yet.]]>
            </message>
            <full-stacktrace>
              <![CDATA[java.lang.UnsupportedOperationException: Not supported yet.
at Assignment_1.Login.checkPhoneNumber(Login.java:88)
at Assignment_1.Login.registerUser(Login.java:57)
at Assignment_1.LoginNGTest.testRegisterUser(LoginNGTest.java:95)
at java.base/jdk.internal.reflect.DirectMethodHandleAccessor.invoke(DirectMethodHandleAccessor.java:103)
at java.base/java.lang.reflect.Method.invoke(Method.java:580)
at org.testng.internal.MethodInvocationHelper.invokeMethod(MethodInvocationHelper.java:124)
at org.testng.internal.Invoker.invokeMethod(Invoker.java:583)
at org.testng.internal.Invoker.invokeTestMethod(Invoker.java:719)
at org.testng.internal.Invoker.invokeTestMethods(Invoker.java:989)
at org.testng.internal.TestMethodWorker.invokeTestMethods(TestMethodWorker.java:125)
at org.testng.internal.TestMethodWorker.run(TestMethodWorker.java:109)
at org.testng.TestRunner.privateRun(TestRunner.java:648)
at org.testng.TestRunner.run(TestRunner.java:505)
at org.testng.SuiteRunner.runTest(SuiteRunner.java:455)
at org.testng.SuiteRunner.runSequentially(SuiteRunner.java:450)
at org.testng.SuiteRunner.privateRun(SuiteRunner.java:415)
at org.testng.SuiteRunner.run(SuiteRunner.java:364)
at org.testng.SuiteRunnerWorker.runSuite(SuiteRunnerWorker.java:52)
at org.testng.SuiteRunnerWorker.run(SuiteRunnerWorker.java:84)
at org.testng.TestNG.runSuitesSequentially(TestNG.java:1208)
at org.testng.TestNG.runSuitesLocally(TestNG.java:1137)
at org.testng.TestNG.runSuites(TestNG.java:1049)
at org.testng.TestNG.run(TestNG.java:1017)
at org.testng.TestNG.privateMain(TestNG.java:1354)
at org.testng.TestNG.main(TestNG.java:1323)
]]>
            </full-stacktrace>
          </exception> <!-- java.lang.UnsupportedOperationException -->
          <reporter-output>
          </reporter-output>
        </test-method> <!-- testRegisterUser -->
        <test-method is-config="true" signature="tearDownMethod()[pri:0, instance:Assignment_1.LoginNGTest@5f282abb]" started-at="2025-04-13T12:37:02Z" name="tearDownMethod" finished-at="2025-04-13T12:37:02Z" duration-ms="0" status="PASS">
          <reporter-output>
          </reporter-output>
        </test-method> <!-- tearDownMethod -->
        <test-method is-config="true" signature="setUpMethod()[pri:0, instance:Assignment_1.LoginNGTest@5f282abb]" started-at="2025-04-13T12:37:02Z" name="setUpMethod" finished-at="2025-04-13T12:37:02Z" duration-ms="0" status="PASS">
          <reporter-output>
          </reporter-output>
        </test-method> <!-- setUpMethod -->
        <test-method signature="testReturnLoginStatus()[pri:0, instance:Assignment_1.LoginNGTest@5f282abb]" started-at="2025-04-13T12:37:02Z" name="testReturnLoginStatus" finished-at="2025-04-13T12:37:02Z" duration-ms="1" status="FAIL">
          <exception class="java.lang.AssertionError">
            <message>
              <![CDATA[expected [] but found [A failed login]]]>
            </message>
            <full-stacktrace>
              <![CDATA[java.lang.AssertionError: expected [] but found [A failed login]
at org.testng.Assert.fail(Assert.java:96)
at org.testng.Assert.failNotEquals(Assert.java:776)
at org.testng.Assert.assertEqualsImpl(Assert.java:137)
at org.testng.Assert.assertEquals(Assert.java:118)
at org.testng.Assert.assertEquals(Assert.java:453)
at org.testng.Assert.assertEquals(Assert.java:463)
at Assignment_1.LoginNGTest.testReturnLoginStatus(LoginNGTest.java:128)
at java.base/jdk.internal.reflect.DirectMethodHandleAccessor.invoke(DirectMethodHandleAccessor.java:103)
at java.base/java.lang.reflect.Method.invoke(Method.java:580)
at org.testng.internal.MethodInvocationHelper.invokeMethod(MethodInvocationHelper.java:124)
at org.testng.internal.Invoker.invokeMethod(Invoker.java:583)
at org.testng.internal.Invoker.invokeTestMethod(Invoker.java:719)
at org.testng.internal.Invoker.invokeTestMethods(Invoker.java:989)
at org.testng.internal.TestMethodWorker.invokeTestMethods(TestMethodWorker.java:125)
at org.testng.internal.TestMethodWorker.run(TestMethodWorker.java:109)
at org.testng.TestRunner.privateRun(TestRunner.java:648)
at org.testng.TestRunner.run(TestRunner.java:505)
at org.testng.SuiteRunner.runTest(SuiteRunner.java:455)
at org.testng.SuiteRunner.runSequentially(SuiteRunner.java:450)
at org.testng.SuiteRunner.privateRun(SuiteRunner.java:415)
at org.testng.SuiteRunner.run(SuiteRunner.java:364)
at org.testng.SuiteRunnerWorker.runSuite(SuiteRunnerWorker.java:52)
at org.testng.SuiteRunnerWorker.run(SuiteRunnerWorker.java:84)
at org.testng.TestNG.runSuitesSequentially(TestNG.java:1208)
at org.testng.TestNG.runSuitesLocally(TestNG.java:1137)
at org.testng.TestNG.runSuites(TestNG.java:1049)
at org.testng.TestNG.run(TestNG.java:1017)
at org.testng.TestNG.privateMain(TestNG.java:1354)
at org.testng.TestNG.main(TestNG.java:1323)
]]>
            </full-stacktrace>
          </exception> <!-- java.lang.AssertionError -->
          <reporter-output>
          </reporter-output>
        </test-method> <!-- testReturnLoginStatus -->
        <test-method is-config="true" signature="tearDownMethod()[pri:0, instance:Assignment_1.LoginNGTest@5f282abb]" started-at="2025-04-13T12:37:02Z" name="tearDownMethod" finished-at="2025-04-13T12:37:02Z" duration-ms="1" status="PASS">
          <reporter-output>
          </reporter-output>
        </test-method> <!-- tearDownMethod -->
        <test-method is-config="true" signature="tearDownClass()[pri:0, instance:Assignment_1.LoginNGTest@5f282abb]" started-at="2025-04-13T12:37:02Z" name="tearDownClass" finished-at="2025-04-13T12:37:02Z" duration-ms="0" status="PASS">
          <reporter-output>
          </reporter-output>
        </test-method> <!-- tearDownClass -->
      </class> <!-- Assignment_1.LoginNGTest -->
    </test> <!-- TestNG tests -->
  </suite> <!-- ST1048177 -->
</testng-results>
